<?xml version="1.0"?>
<robot xmlns:xacro="http://www.ros.org/wiki/xacro" >
    
    <material name="white">
        <color rgba="1 1 1 1"/>
    </material>

    <material name="orange">
        <color rgba="1 0.3 0.1 1"/>
    </material>

    <material name="blue">
        <color rgba="0.2 0.2 1 1"/>
    </material>


    <material name="black">
        <color rgba="0 0 0 1"/>
    </material>

    <!--DUMMY: base link-->
    <link name="base_link"></link>

    <joint name="chassis_joint" type="fixed">
      <parent link="base_link"/>
      <child link="chassis_link"/>
      <origin xyz = "0 0 0"/>
    </joint>

    <link name="chassis_link">
    <inertial>
      <origin
        xyz="-2.7756E-17 0.22033 -0.20541"
        rpy="0 0 0" />
      <mass
        value="431.73" />
      <inertia
        ixx="103.67"
        ixy="2.3121E-14"
        ixz="1.1675E-15"
        iyy="37.727"
        iyz="-13.991"
        izz="120.86" />
    </inertial>
    <visual>
      <origin
        xyz="0 0 0"
        rpy="0 0 0" />
      <geometry>
        <mesh
          filename="package://new_eudald_massana/meshes/base_link.STL" />
      </geometry>
      <material name="orange"/>
    </visual>
    <collision>
      <origin
        xyz="0 0 0"
        rpy="0 0 0" />
      <geometry>
        <mesh
          filename="package://new_eudald_massana/meshes/base_link.STL" />
      </geometry>
    </collision>
  </link>


  <link name="left_wheel_link">
    <inertial>
      <origin xyz="0 0 -0.025" rpy="0 0 0" />
      <mass value="122.72" />
      <inertia
        ixx="5.2603"
        ixy="0"
        ixz="0"
        iyy="5.2603"
        iyz="0"
        izz="7.8617" />
    </inertial>
    <visual>
      <origin
        xyz="0 0 0"
        rpy="0 0 0" />
      <geometry>
        <mesh
          filename="package://new_eudald_massana/meshes/left_wheel_link.STL" />
      </geometry>
      <material name="black"/>
    </visual>
    <collision>
      <origin
        xyz="0 0 0"
        rpy="0 0 0" />
      <geometry>
        <mesh
          filename="package://new_eudald_massana/meshes/left_wheel_link.STL" />
      </geometry>
    </collision>
  </link>


  <joint name="left_wheel_joint" type="continuous">
    <origin
      xyz="-0.7 0 -0.25"
      rpy="-1.5708 0 1.5708" />
    <parent
      link="chassis_link" />
    <child
      link="left_wheel_link" />
    <axis
      xyz="0 0 -1" />
  </joint>



  <joint name="left_wheel_joint" type="continuous">
        <parent link="base_link"/>
        <child link="left_wheel_link"/>
        <origin xyz="0 -0.31757 0" rpy="1.5708 0 0"/>
        <axis xyz="0 0 1"/>
  </joint>


  <link
    name="right_wheel_link">
    <inertial>
      <origin
        xyz="0 0 0.025"
        rpy="0 0 0" />
      <mass
        value="122.72" />
      <inertia
        ixx="5.2603"
        ixy="0"
        ixz="0"
        iyy="5.2603"
        iyz="0"
        izz="7.8617" />
    </inertial>
    <visual>
      <origin
        xyz="0 0 0"
        rpy="0 0 0" />
      <geometry>
        <mesh
          filename="package://new_eudald_massana/meshes/right_wheel_link.STL" />
      </geometry>
      <material name="black"/>
    </visual>
    <collision>
      <origin
        xyz="0 0 0"
        rpy="0 0 0" />
      <geometry>
        <mesh
          filename="package://new_eudald_massana/meshes/right_wheel_link.STL" />
      </geometry>
    </collision>
  </link>
  <joint
    name="right_wheel_joint"
    type="continuous">
    <origin
      xyz="0.7 0 -0.25"
      rpy="-1.5708 0 1.5708" />
    <parent
      link="chassis_link" />
    <child
      link="right_wheel_link" />
    <axis
      xyz="0 0 1" />
  </joint>
  <link
    name="caster_base_link">
    <inertial>
      <origin
        xyz="-0.092812 -0.29573 -0.31161"
        rpy="0 0 0" />
      <mass
        value="19.859" />
      <inertia
        ixx="2.6905"
        ixy="-0.13364"
        ixz="-0.20909"
        iyy="0.90408"
        iyz="-0.66595"
        izz="2.5177" />
    </inertial>
    <visual>
      <origin
        xyz="0 0 0"
        rpy="0 0 0" />
      <geometry>
        <mesh
          filename="package://new_eudald_massana/meshes/caster_base_link.STL" />
      </geometry>
      <material name="blue"/>
    </visual>
    <collision>
      <origin
        xyz="0 0 0"
        rpy="0 0 0" />
      <geometry>
        <mesh
          filename="package://new_eudald_massana/meshes/caster_base_link.STL" />
      </geometry>
    </collision>
  </link>
  <joint
    name="caster_base_joint"
    type="continuous">
    <origin
      xyz="0 1.5 0"
      rpy="0 0 -0.57871" />
    <parent
      link="chassis_link" />
    <child
      link="caster_base_link" />
    <axis
      xyz="0 0 -1" />
  </joint>
  <link
    name="caster_wheel_link">
    <inertial>
      <origin
        xyz="0 0 5.5511E-17"
        rpy="0 0 0" />
      <mass
        value="22.089" />
      <inertia
        ixx="0.29798"
        ixy="0"
        ixz="0"
        iyy="0.29798"
        iyz="0"
        izz="0.36585" />
    </inertial>
    <visual>
      <origin
        xyz="0 0 0"
        rpy="0 0 0" />
      <geometry>
        <mesh
          filename="package://new_eudald_massana/meshes/caster_wheel_link.STL" />
      </geometry>
      <material name="black"/>
    </visual>
    <collision>
      <origin
        xyz="0 0 0"
        rpy="0 0 0" />
      <geometry>
        <mesh
          filename="package://new_eudald_massana/meshes/caster_wheel_link.STL" />
      </geometry>
    </collision>
  </link>
  <joint
    name="caster_wheel_joint"
    type="continuous">
    <origin
      xyz="0 -0.75 -0.425"
      rpy="0 1.5708 0" />
    <parent
      link="caster_base_link" />
    <child
      link="caster_wheel_link" />
    <axis
      xyz="0 0 -1" />
  </joint>


</robot>